Workbook

Sheet 說明
A1: Ch4 標準曲線與線性迴歸：OLS 逐步計算與 1/x² 加權迴歸（WLS）
A2: 對應網頁：ch04.html ｜ 黃色儲存格＝可以改成你自己的數據；其他是公式，請不要直接覆蓋。
A4: 這本活頁簿在做什麼
A5: 「標準曲線迴歸」工作表：鈉標準曲線 5 個濃度點（Nielsen 章末習題4 Group A），用 SLOPE/INTERCEPT/RSQ/STEYX 逐步算出 y=ax+b、r²、殘差標準誤，再把每一點的殘差算出來，最後反推一個未知樣品訊號的濃度。
A6: 「WLS_1x2加權」工作表：HPLC 咖啡因 5 個濃度（1~100 ppm）各測 3 次，示範當高濃度訊號的變異明顯比低濃度大（異方差）時，怎麼用 SUMPRODUCT 公式做 1/x² 加權最小平方法（WLS），並把 OLS 與 WLS 的斜率、截距、每一點回算濃度的相對誤差 %RE 並排比較。
A7: 怎麼用
A8: 1. 黃色是原始數據（濃度、訊號），其他都是活公式，C 欄印出公式原文對照。
A9: 2.「標準曲線迴歸」把 B15 的未知樣品訊號改一改，看反推濃度怎麼變；也可以改 A2:B6 的原始數據看整條線怎麼變。
A10: 3.「WLS_1x2加權」看『%RE 回算對照』表：OLS 在 1 ppm（最低濃度）那一列的 %RE 特別大，WLS 1/x² 那一列則小很多——這就是加權要解決的問題。
A11: 4.「對照R答案」工作表核對 Excel 算出來的與 R 的答案是否一致。
A12: 用 Excel 資料分析工具箱算迴歸（選用，適用於標準曲線）
A13: 啟用方式：檔案 → 選項 → 增益集 → 管理『Excel 增益集』→ 勾選『分析工具箱』→ 確定，『資料』分頁會多一個『資料分析』按鈕。
... A19: 『濃度範圍很寬』本身不是自動加權的理由，要先看：①各濃度重複的 SD 是否隨濃度一路變大；②OLS 殘差是否呈喇叭狀。選權重不能只看 r²（三個模型的 r² 幾乎一樣），要看低濃度端的回算 %RE 是否明顯改善。

Sheet 標準曲線迴歸
A1: 濃度 x (ug/mL) | B1: 訊號 y
A2: 1 | B2: 0.05
A3: 3 | B3: 0.14
A4: 5 | B4: 0.242
A5: 10 | B5: 0.521
A6: 20 | B6: 0.998
A8: 項目 | B8: 結果 | C8: 公式 | D8: 說明
A9: n（標準品數） | B9: =COUNT(A2:A6) | C9: '=COUNT(A2:A6)
A10: 斜率 a (SLOPE) | B10: =SLOPE(B2:B6,A2:A6) | C10: '=SLOPE(B2:B6,A2:A6) | D10: 靈敏度：訊號隨濃度增加的幅度
A11: 截距 b (INTERCEPT) | B11: =INTERCEPT(B2:B6,A2:A6) | C11: '=INTERCEPT(B2:B6,A2:A6) | D11: 濃度為0時的空白背景訊號
A12: 判定係數 r² (RSQ) | B12: =RSQ(B2:B6,A2:A6) | C12: '=RSQ(B2:B6,A2:A6) | D12: y 的變異能被 x 解釋的比例
A13: 相關係數 r (CORREL) | B13: =CORREL(A2:A6,B2:B6) | C13: '=CORREL(A2:A6,B2:B6) | D13: r=√r²；經驗法則 r≥0.997 才理想
A14: 殘差標準誤 STEYX | B14: =STEYX(B2:B6,A2:A6) | C14: '=STEYX(B2:B6,A2:A6) | D14: 殘差的標準差，越小代表點越貼線
A15: 未知樣品訊號 y_obs | B15: 0.555 | D15: 可以改成你自己的訊號值試試
A16: 反推濃度 x_pred | B16: =(B15-B11)/B10 | C16: '=(B15-B11)/B10 | D16: x=(y−b)/a；千萬別把方向弄反！
A18: 殘差表：逐點檢查『直線』這個假設站不站得住腳（應隨機散布在 0 附近，不能有彎曲趨勢）。
A19: x | B19: y實測 | C19: y預測 (=a·x+b) | D19: 殘差 (=y實測−y預測)
A20: =A2 | B20: =B2 | C20: =B10*A20+B11 | D20: =B20-C20
A21: =A3 | B21: =B3 | C21: =B10*A21+B11 | D21: =B21-C21
A22: =A4 | B22: =B4 | C22: =B10*A22+B11 | D22: =B22-C22
A23: =A5 | B23: =B5 | C23: =B10*A23+B11 | D23: =B23-C23
A24: =A6 | B24: =B6 | C24: =B10*A24+B11 | D24: =B24-C24

Sheet WLS_1x2加權
A1: 濃度 x (ppm) | B1: 面積 y (訊號)
A2: 1 | B2: 101
A3: 1 | B3: 99
A4: 1 | B4: 102
A5: 5 | B5: 498
A6: 5 | B6: 505
A7: 5 | B7: 492
A8: 10 | B8: 1005
A9: 10 | B9: 992
A10: 10 | B10: 1018
A11: 50 | B11: 4930
A12: 50 | B12: 5070
A13: 50 | B13: 5005
... A16: 100 | B16: 10040
A18: 加權最小平方法：權重 w=1/x²，直接用 SUMPRODUCT 算出加權平方和，不需要陣列公式。
A19: 項目 | B19: 結果 | C19: 公式 | D19: 說明
A20: Σw （w=1/x²） | B20: =SUMPRODUCT(1/A2:A16^2) | C20: '=SUMPRODUCT(1/A2:A16^2)
A21: Σw·x | B21: =SUMPRODUCT(1/A2:A16^2,A2:A16) | C21: '=SUMPRODUCT(1/A2:A16^2,A2:A16)
A22: Σw·y | B22: =SUMPRODUCT(1/A2:A16^2,B2:B16) | C22: '=SUMPRODUCT(1/A2:A16^2,B2:B16)
A23: Σw·x² | B23: =SUMPRODUCT(1/A2:A16^2,A2:A16,A2:A16) | C23: '=SUMPRODUCT(1/A2:A16^2,A2:A16,A2:A16)
A24: Σw·x·y | B24: =SUMPRODUCT(1/A2:A16^2,A2:A16,B2:B16) | C24: '=SUMPRODUCT(1/A2:A16^2,A2:A16,B2:B16)
A25: WLS 斜率 a_w | B25: =(B20*B24-B21*B22)/(B20*B23-B21^2) | C25: '=(B20*B24-B21*B22)/(B20*B23-B21^2) | D25: 加權常態方程式解出來的斜率
A26: WLS 截距 b_w | B26: =(B22-B25*B21)/B20 | C26: '=(B22-B25*B21)/B20
A27: OLS 斜率 a (SLOPE，對照用) | B27: =SLOPE(B2:B16,A2:A16) | C27: '=SLOPE(B2:B16,A2:A16)
A28: OLS 截距 b (INTERCEPT，對照用) | B28: =INTERCEPT(B2:B16,A2:A16) | C28: '=INTERCEPT(B2:B16,A2:A16)
A30: %RE 回算對照：把每一筆標準品的訊號當成『未知樣品』反推濃度，看回算的相對誤差 %RE。
A31: 濃度 x | B31: 面積 y | C31: OLS回算濃度 | D31: OLS %RE | E31: WLS回算濃度 | F31: WLS %RE
A32: =A2 | B32: =B2 | C32: =(B32-B28)/B27 | D32: =(C32-A32)/A32*100 | E32: =(B32-B26)/B25 | F32: =(E32-A32)/A32*100
A33: =A3 | B33: =B3 | C33: =(B33-B28)/B27 | D33: =(C33-A33)/A33*100 | E33: =(B33-B26)/B25 | F33: =(E33-A33)/A33*100
A34: =A4 | B34: =B4 | C34: =(B34-B28)/B27 | D34: =(C34-A34)/A34*100 | E34: =(B34-B26)/B25 | F34: =(E34-A34)/A34*100
A35: =A5 | B35: =B5 | C35: =(B35-B28)/B27 | D35: =(C35-A35)/A35*100 | E35: =(B35-B26)/B25 | F35: =(E35-A35)/A35*100
A36: =A6 | B36: =B6 | C36: =(B36-B28)/B27 | D36: =(C36-A36)/A36*100 | E36: =(B36-B26)/B25 | F36: =(E36-A36)/A36*100
A37: =A7 | B37: =B7 | C37: =(B37-B28)/B27 | D37: =(C37-A37)/A37*100 | E37: =(B37-B26)/B25 | F37: =(E37-A37)/A37*100
A38: =A8 | B38: =B8 | C38: =(B38-B28)/B27 | D38: =(C38-A38)/A38*100 | E38: =(B38-B26)/B25 | F38: =(E38-A38)/A38*100
A39: =A9 | B39: =B9 | C39: =(B39-B28)/B27 | D39: =(C39-A39)/A39*100 | E39: =(B39-B26)/B25 | F39: =(E39-A39)/A39*100
A40: =A10 | B40: =B10 | C40: =(B40-B28)/B27 | D40: =(C40-A40)/A40*100 | E40: =(B40-B26)/B25 | F40: =(E40-A40)/A40*100
A41: =A11 | B41: =B11 | C41: =(B41-B28)/B27 | D41: =(C41-A41)/A41*100 | E41: =(B41-B26)/B25 | F41: =(E41-A41)/A41*100
A42: =A12 | B42: =B12 | C42: =(B42-B28)/B27 | D42: =(C42-A42)/A42*100 | E42: =(B42-B26)/B25 | F42: =(E42-A42)/A42*100
A43: =A13 | B43: =B13 | C43: =(B43-B28)/B27 | D43: =(C43-A43)/A43*100 | E43: =(B43-B26)/B25 | F43: =(E43-A43)/A43*100
A44: =A14 | B44: =B14 | C44: =(B44-B28)/B27 | D44: =(C44-A44)/A44*100 | E44: =(B44-B26)/B25 | F44: =(E44-A44)/A44*100
...

Sheet 對照R答案
A1: 項目 | B1: Excel 算出來 | C1: R 的答案 | D1: 一致？ | E1: 來源儲存格
A2: 標準曲線斜率 a | B2: ='標準曲線迴歸'!B10 | C2: 0.05039948 | D2: =IF(ABS(B2-C2)<=2.519974003466205e-05,"✓","✗") | E2: '標準曲線迴歸'!B10
A3: 標準曲線截距 b | B3: ='標準曲線迴歸'!B11 | C3: -0.0029159445 | D3: =IF(ABS(B3-C3)<=1.4579722703639049e-06,"✓","✗") | E3: '標準曲線迴歸'!B11
A4: 判定係數 r² | B4: ='標準曲線迴歸'!B12 | C4: 0.99902532 | D4: =IF(ABS(B4-C4)<=0.0004995126620084015,"✓","✗") | E4: '標準曲線迴歸'!B12
A5: 相關係數 r | B5: ='標準曲線迴歸'!B13 | C5: 0.99951254 | D5: =IF(ABS(B5-C5)<=0.000499756271600668,"✓","✗") | E5: '標準曲線迴歸'!B13
A6: 殘差標準誤 STEYX | B6: ='標準曲線迴歸'!B14 | C6: 0.013807823 | D6: =IF(ABS(B6-C6)<=6.9039115580005005e-06,"✓","✗") | E6: '標準曲線迴歸'!B14
A7: 反推濃度 x_pred (y=0.555) | B7: ='標準曲線迴歸'!B16 | C7: 11.069875 | D7: =IF(ABS(B7-C7)<=0.0055349375010745995,"✓","✗") | E7: '標準曲線迴歸'!B16
A8: 第1點殘差 | B8: ='標準曲線迴歸'!D20 | C8: 0.0025164645 | D8: =IF(ABS(B8-C8)<=1e-06,"✓","✗") | E8: '標準曲線迴歸'!D20
A9: WLS 1/x² 斜率 | B9: ='WLS_1x2加權'!B25 | C9: 100.15188 | D9: =IF(ABS(B9-C9)<=0.0500759377272555,"✓","✗") | E9: 'WLS_1x2加權'!B25
A10: WLS 1/x² 截距 | B10: ='WLS_1x2加權'!B26 | C10: 0.43154591 | D10: =IF(ABS(B10-C10)<=0.000215772955180477,"✓","✗") | E10: 'WLS_1x2加權'!B26
A11: OLS 斜率（對照） | B11: ='WLS_1x2加權'!B27 | C11: 100.42937 | D11: =IF(ABS(B11-C11)<=0.050214683945203495,"✓","✗") | E11: 'WLS_1x2加權'!B27
A12: OLS 截距（對照） | B12: ='WLS_1x2加權'!B28 | C12: -3.7883473 | D12: =IF(ABS(B12-C12)<=0.00189417364742011,"✓","✗") | E12: 'WLS_1x2加權'!B28
A13: 1ppm OLS %RE | B13: ='WLS_1x2加權'!D32 | C13: 4.3403434 | D13: =IF(ABS(B13-C13)<=0.0001,"✓","✗") | E13: 'WLS_1x2加權'!D32
A14: 1ppm WLS 1/x² %RE | B14: ='WLS_1x2加權'!F32 | C14: 0.41594691 | D14: =IF(ABS(B14-C14)<=0.0001,"✓","✗") | E14: 'WLS_1x2加權'!F32
A16: 如果你改了黃色儲存格的數據，這裡當然會變成 ✗——那是因為 R 的答案是用原始教材數據算的。
