Workbook

Sheet 說明
A1: Ch10 實戰案例：滴定標定與 HPLC 農藥殘留的量測不確定度預算
A2: 對應網頁：ch10.html ｜ 黃色儲存格＝可以改成你自己的數據；其他是公式，請不要直接覆蓋。
A4: 這本活頁簿在做什麼
A5: 重現教科書兩個國際範例：①用 KHP 標定 NaOH 濃度（QUAM Example A2）；②HPLC/GC 測麵包中農藥殘留（QUAM Example A4）。
A6: 兩者都是「乘除模型」——所以不確定度合成一律用「相對不確定度」（u(x)/x，沒有單位），公式是：相對合成 = SQRT(SUMSQ(各項相對u))。
A7: 「滴定NaOH標定」工作表：先算出濃度，再一項一項列出不確定度預算，看誰是老大（V_T 占 52%）。
A8: 「HPLC農藥殘留」工作表：內部驗證法的三大成分（精密度／回收率偏倚／均勻性），加上符合性判定。
A9: 怎麼用
A10: 1. 黃色是可以改的數據；改了以後，右邊所有公式（包含 u²占比）都會自動重算。
A11: 2. 試著把 V_T 從 18.64 改成 49（滴定管接近滿管程），看 u_c 怎麼變小——這就是「改善策略」那一段在算的事。
A12: 3. HPLC 工作表把 MRL（法規限量）改一改，看「符合／不符合／灰色地帶」怎麼變。
A13: 4.「對照R答案」工作表核對 Excel 與 R 是否一致。
... A18: 不確定度預算是逐項代公式，屬於「量測不確定度評估」而不是統計檢定或迴歸，Excel 的資料分析工具箱（t 檢定/F 檢定/ANOVA/迴歸）用不上；本活頁簿全部用一般函數（SQRT、SUMSQ、IF）現場計算。

Sheet 滴定NaOH標定
A1: Step 1：量測模型的各輸入量（黃色可改）
A2: 項目 | B2: 數值 | C2: 公式 | D2: 說明
A3: m(KHP)：KHP 質量 (g) | B3: 0.3888 | D3: 稱取的 KHP 淨重
A4: P(KHP)：純度 | B4: 1 | D4: 證書純度（小數）
A5: M(KHP)：莫耳質量 (g/mol) | B5: 204.2212 | D5: 由 IUPAC 原子量計算
A6: V_T：滴定體積 (mL) | B6: 18.64 | D6: 自動滴定儀 pH 電極判定終點
A7: c(NaOH)：標定濃度 (mol/L) | B7: =1000*B3*B4/(B5*B6) | C7: '=1000*B3*B4/(B5*B6) | D7: 量測模型：1000×m×P/(M×V_T)
A9: u(V_T) 的解剖：滴定體積的三個不確定度來源
A10: 項目 | B10: 數值 | C10: 公式 | D10: 說明
A11: ① 滴定管校正 半寬 a (mL) | B11: 0.01 | D11: A 級滴定管證書 ±0.01 mL
A12: u(校正)：三角形分布 (mL) | B12: =B11/SQRT(6) | C12: '=B11/SQRT(6) | D12: 三角形分布除數 √6
A13: ② 水的體積膨脹係數 (/℃) | B13: 0.00021 | D13: 查表常數
A14: 溫度變動 ±ΔT (℃) | B14: 4 | D14: 實驗室溫度變動範圍
A15: 溫度效應 半寬 a (mL) | B15: =B6*B13*B14 | C15: '=B6*B13*B14 | D15: V_T × 膨脹係數 × ΔT
A16: u(溫度)：矩形分布 (mL) | B16: =B15/SQRT(3) | C16: '=B15/SQRT(3) | D16: 矩形分布除數 √3
A17: ③ 終點判讀 半寬 a (mL) | B17: 0.003 | D17: pH 曲線轉折與理論當量點的偏差
A18: u(終點)：矩形分布 (mL) | B18: =B17/SQRT(3) | C18: '=B17/SQRT(3) | D18: 矩形分布除數 √3
A19: u(V_T) 三項合成 (mL) | B19: =SQRT(SUMSQ(B12,B16,B18)) | C19: '=SQRT(SUMSQ(B12,B16,B18)) | D19: SQRT(SUMSQ(校正,溫度,終點)) ≈ 0.0101，QUAM 保守取 0.013（見下方採用值）
A20: u(V_T)：採用值 (mL) | B20: 0.013 | D20: QUAM 原文較保守的取值，下方主預算表採用這一個
A22: Step 3/4：不確定度預算表（乘除模型，用相對不確定度）
A23: 來源 | B23: 數值 x | C23: 分布 | D23: 除數 | E23: 標準不確定度 u | F23: 相對 u(x)/x | G23: u²占比 (%)
A24: u_rep：重複性 相對標準不確定度 | B24: 0.0005 | D24: 過往滴定的重複變異（合併所有操作），先佔一列避免與下面預算表衝突
A25: u(m)：質量標準不確定度 (g) | B25: 0.00013 | D25: 第7章天平案例：解析度+校正+重複
A26: a(P)：純度半寬（矩形） | B26: 0.0005 | D26: 證書 ±0.0005
A27: u(P) 計算值：矩形分布 | B27: =B26/SQRT(3) | C27: '=B26/SQRT(3) | D27: u(P) = a/√3 ≈ 0.0002887；下方主預算表採用教材/QUAM 取值 0.00029
A28: u(M)：莫耳質量標準不確定度 (g/mol) | B28: 0.0038 | D28: IUPAC 原子量不確定度表
A29: 重複性 rep | B29: 1 | C29: 直接給定（歷史滴定重複變異） | D29: — | E29: =B24 | F29: =B24/1 | G29: =F29^2/B35^2*100
A30: 質量 m(KHP) | B30: =B3 | C30: 合成（天平：解析度+校正+重複） | D30: — | E30: =B25 | F30: =B25/B3 | G30: =F30^2/B35^2*100
A31: 純度 P(KHP) | B31: =B4 | C31: 矩形 ±0.0005（=0.0005/√3≈0.0002887，教材採用 0.00029） | D31: √3 | E31: 0.00029 | F31: =E31/B4 | G31: =F31^2/B35^2*100
A32: 莫耳質量 M(KHP) | B32: =B5 | C32: 常態（IUPAC 給定為 u） | D32: 1 | E32: =B28 | F32: =B28/B5 | G32: =F32^2/B35^2*100
A33: 滴定體積 V_T | B33: =B6 | C33: 合成（校正+溫度+終點，見上表） | D33: 1 | E33: =B20 | F33: =B20/B6 | G33: =F33^2/B35^2*100
A35: 相對合成不確定度 u_c(c)/c | B35: =SQRT(SUMSQ(F29,F30,F31,F32,F33)) | C35: '=SQRT(SUMSQ(F29,F30,F31,F32,F33)) | D35: SQRT(SUMSQ(五項相對 u))——先平方、加總、再開根號
A36: u_c(c)：合成標準不確定度 (mol/L) | B36: =B7*B35 | C36: '=B7*B35 | D36: c(NaOH) × 相對合成
A37: U：擴展不確定度 (k=2) | B37: =2*B36 | C37: '=2*B36 | D37: k=2，約 95%
A38: 報告：c(NaOH) = (0.10214 ± 0.00020) mol/L（k=2）
A40: 改善策略：讓滴定體積接近 50 mL 滿管程（多稱 KHP）
A41: 項目 | B41: 數值 | C41: 公式 | D41: 說明
A42: V_T 改善後 (mL) | B42: 49 | D42: 多稱約 2.6 倍 KHP，滴定體積接近滿管程
A43: m(KHP) 放大倍數 | B43: 2.6 | D43: 配合 V_T 加大，同比例多稱 KHP
A44: V_T 改善後的相對 u | B44: =B20/B42 | C44: '=B20/B42 | D44: u(V_T) 不變，只是 V_T 變大
...

Sheet HPLC農藥殘留
A1: Step 3：內部驗證法的三大成分（QUAM Table A4.4）
A2: 來源 | B2: 數值 x | C2: 分布 | D2: 除數 | E2: 標準不確定度 u | F2: 相對 u(x)/x | G2: u²占比 (%)
A3: 精密度 Precision | B3: 1 | C3: 直接給定（不同類型樣品雙重複分析的中間精密度） | D3: — | E3: 0.27 | F3: =E3/B3 | G3: =F3^2/B8^2*100
A4: 偏倚 Bias（回收率） | B4: 0.9 | C4: 加標回收實驗：平均回收 90%，其 SD 與顯著性檢定 | D4: — | E4: 0.043 | F4: =E4/B4 | G4: =F4^2/B8^2*100
A5: 均勻性 Homogeneity | B5: 1 | C5: 模型估計最壞情境（農藥可能只在麵包表面） | D5: — | E5: 0.2 | F5: =E5/B5 | G5: =F5^2/B8^2*100
A7: 項目 | B7: 結果 | C7: 公式 | D7: 說明
A8: 相對合成不確定度 | B8: =SQRT(SUMSQ(F3,F4,F5)) | C8: '=SQRT(SUMSQ(F3,F4,F5)) | D8: 三大成分平方和開根號
A10: P_raw：儀器測得未修正結果 (mg/kg) | B10: 1 | D10: 層析儀讀值
A11: Rec：回收率 | B11: 0.9 | D11: 同上表回收率
A12: P_op：回收率修正後結果 (mg/kg) | B12: =B10/B11 | C12: '=B10/B11 | D12: 除以回收率修正偏倚
A13: u_c(P_op) (mg/kg) | B13: =B12*B8 | C13: '=B12*B8 | D13: P_op × 相對合成
A14: U：擴展不確定度 (k=2, mg/kg) | B14: =2*B13 | C14: '=2*B13 | D14: k=2，約 95%
A15: 報告：P_op = (1.11 ± 0.75) mg/kg（k=2）——與 QUAM Table A4.5 一致
A17: 進階：用雙重複對數據自己算精密度項（估短期重複性 RSD）
A18: 樣品 a | B18: 樣品 b | C18: 相對差 d=(a-b)/((a+b)/2) | D18: d²
A19: 0.42 | B19: 0.39 | C19: =(A19-B19)/((A19+B19)/2) | D19: =C19^2
A20: 1.13 | B20: 0.97 | C20: =(A20-B20)/((A20+B20)/2) | D20: =C20^2
A21: 0.27 | B21: 0.3 | C21: =(A21-B21)/((A21+B21)/2) | D21: =C21^2
A22: 0.88 | B22: 0.71 | C22: =(A22-B22)/((A22+B22)/2) | D22: =C22^2
A23: 0.55 | B23: 0.6 | C23: =(A23-B23)/((A23+B23)/2) | D23: =C23^2
A24: 1.62 | B24: 1.28 | C24: =(A24-B24)/((A24+B24)/2) | D24: =C24^2
A25: 0.31 | B25: 0.35 | C25: =(A25-B25)/((A25+B25)/2) | D25: =C25^2
A26: 0.74 | B26: 0.8 | C26: =(A26-B26)/((A26+B26)/2) | D26: =C26^2
A27: Σd² | B27: =SUM(D19:D26) | C27: '=SUM(D19:D26) | D27: 8 對雙重複的相對差平方和
A28: 對數 n | B28: =COUNT(A19:A26) | C28: '=COUNT(A19:A26) | D28: 共 8 對
A29: RSD（短期重複性） | B29: =SQRT(B27/(2*B28)) | C29: '=SQRT(B27/(2*B28)) | D29: SQRT(Σd²/(2n))——只反映短期變異，比長期中間精密度 0.27 小得多
A31: 符合性判定（保守決策規則）
A32: 項目 | B32: 結果 | C32: 公式 | D32: 說明
A33: MRL：法規限量 (mg/kg) | B33: 2 | D33: 可改成 1.5 看灰色地帶
A34: 下限 = P_op − U | B34: =B12-B14 | C34: '=B12-B14
A35: 上限 = P_op + U | B35: =B12+B14 | C35: '=B12+B14
A36: 判定 | B36: =IF(B34>B33,"不符合",IF(B35<=B33,"符合","灰色地帶")) | C36: '=IF(B34>B33,"不符合",IF(B35<=B33,"符合","灰色地帶")) | D36: 下限超過限量才判不符合；上限沒超過才判符合；其餘是灰色地帶

Sheet 對照R答案
A1: 項目 | B1: Excel 算出來 | C1: R 的答案 | D1: 一致？ | E1: 來源儲存格
A2: c(NaOH) 標定濃度 | B2: ='滴定NaOH標定'!B7 | C2: 0.10213616 | D2: =IF(ABS(B2-C2)<=5.1068079850000004e-05,"✓","✗") | E2: '滴定NaOH標定'!B7
A3: 滴定相對合成不確定度 | B3: ='滴定NaOH標定'!B35 | C3: 0.00096573586 | D3: =IF(ABS(B3-C3)<=4.828679302500001e-07,"✓","✗") | E3: '滴定NaOH標定'!B35
A4: 滴定 u_c | B4: ='滴定NaOH標定'!B36 | C4: 9.8636552e-05 | D4: =IF(ABS(B4-C4)<=4.931827604e-08,"✓","✗") | E4: '滴定NaOH標定'!B36
A5: 滴定 U (k=2) | B5: ='滴定NaOH標定'!B37 | C5: 0.0001972731 | D5: =IF(ABS(B5-C5)<=9.863655210000001e-08,"✓","✗") | E5: '滴定NaOH標定'!B37
A6: V_T 三項合成 u(V_T) | B6: ='滴定NaOH標定'!B19 | C6: 0.010069102 | D6: =IF(ABS(B6-C6)<=5.03455094e-06,"✓","✗") | E6: '滴定NaOH標定'!B19
A7: V_T 對變異數占比 (%) | B7: ='滴定NaOH標定'!G33 | C7: 52.152865 | D7: =IF(ABS(B7-C7)<=0.026076432545,"✓","✗") | E7: '滴定NaOH標定'!G33
A8: 改善後相對合成 | B8: ='滴定NaOH標定'!B46 | C8: 0.00064913153 | D8: =IF(ABS(B8-C8)<=3.2456576415000005e-07,"✓","✗") | E8: '滴定NaOH標定'!B46
A9: HPLC 相對合成不確定度 | B9: ='HPLC農藥殘留'!B8 | C9: 0.33938579 | D9: =IF(ABS(B9-C9)<=0.0001696928962,"✓","✗") | E9: 'HPLC農藥殘留'!B8
A10: HPLC P_op | B10: ='HPLC農藥殘留'!B12 | C10: 1.1111111 | D10: =IF(ABS(B10-C10)<=0.0005555555555000001,"✓","✗") | E10: 'HPLC農藥殘留'!B12
A11: HPLC u_c(P_op) | B11: ='HPLC農藥殘留'!B13 | C11: 0.37709532 | D11: =IF(ABS(B11-C11)<=0.0001885476624,"✓","✗") | E11: 'HPLC農藥殘留'!B13
A12: HPLC U (k=2) | B12: ='HPLC農藥殘留'!B14 | C12: 0.75419065 | D12: =IF(ABS(B12-C12)<=0.00037709532485,"✓","✗") | E12: 'HPLC農藥殘留'!B14
A13: 雙重複 RSD | B13: ='HPLC農藥殘留'!B29 | C13: 0.10271962 | D13: =IF(ABS(B13-C13)<=5.135980980000001e-05,"✓","✗") | E13: 'HPLC農藥殘留'!B29
A15: 如果你改了黃色儲存格的數據，這裡當然會變成 ✗——那是因為 R 的答案是用原始教材數據算的。
