Workbook

Sheet 說明
A1: Ch12 進階案例：LC-MS/MS 基質效應、SIL-IS 與 1/x 加權校正的不確定度
A2: 對應網頁：ch12.html ｜ 黃色儲存格＝可以改成你自己的數據；其他是公式，請不要直接覆蓋。
A4: 這本活頁簿在做什麼
A5: 以蝦仁中氯黴素（LC-MS/MS，MRPL=0.3 μg/kg）為例，重現三個 LC-MS/MS 特有的統計工具：
A6: ①Matuszewski 三組實驗（ME%基質效應／RE%萃取回收／PE%流程效率，都用 SLOPE 算斜率再相除）
A7: ②同位素內標（SIL-IS）面積比校正——同樣的三個指標，比較補償前後的差異
A8: ③1/x 加權迴歸——痕量分析必備，用 SUMPRODUCT 手刻加權最小平方公式（Excel 沒有內建加權迴歸）
A9: 最後一張工作表把四個不確定度成分（中間精密度／均勻性／校正殘餘／回收率）合成，並做限量符合性判定。
A10: 怎麼用
A11: 1. 黃色是可以改的數據；改了以後所有公式自動重算。
A12: 2.「Matuszewski基質效應」工作表的 x、y 數據是本活頁簿設計的示範數據（零截距直線），斜率設計成與 R 案例的 45200/38400/34600 完全一致——這樣你可以用 Excel 的 SLOPE() practice 算斜率比值，效果與 R 一樣。
A13: 3.「加權迴歸1x」工作表可以比較 OLS 與 1/x 加權在低濃度的回算誤差差多大。
... A19: SLOPE() 本身可以對照工具箱的『迴歸』分析（斜率＝迴歸係數），但 Matuszewski 比值、1/x 加權迴歸、不確定度預算都是逐項代公式，工具箱做不到，本章一律用一般函數現場計算。

Sheet Matuszewski基質效應
A1: 示範數據：濃度 x 與三組校正線的波峰面積 y（零截距，斜率＝R 案例的值）
A2: 濃度 x (相對單位) | B2: yA 溶液標準 | C2: yB 萃取後添加 | D2: yC 添加後萃取
A3: 0 | B3: 0 | C3: 0 | D3: 0
A4: 2 | B4: 90400 | C4: 76800 | D4: 69200
A5: 5 | B5: 226000 | C5: 192000 | D5: 173000
A6: 10 | B6: 452000 | C6: 384000 | D6: 346000
A7: 20 | B7: 904000 | C7: 768000 | D7: 692000
A9: 項目 | B9: 結果 | C9: 公式 | D9: 說明
A10: 斜率 A（溶液標準） | B10: =SLOPE(B3:B7,A3:A7) | C10: '=SLOPE(B3:B7,A3:A7) | D10: 理想電離效率
A11: 斜率 B（萃取後添加） | B11: =SLOPE(C3:C7,A3:A7) | C11: '=SLOPE(C3:C7,A3:A7) | D11: 純電離表現（沒有萃取步驟）
A12: 斜率 C（添加後萃取） | B12: =SLOPE(D3:D7,A3:A7) | C12: '=SLOPE(D3:D7,A3:A7) | D12: 電離+萃取損失（像真樣品）
A13: ME%：基質效應 | B13: =(B11/B10-1)*100 | C13: '=(B11/B10-1)*100 | D13: (B/A−1)×100，負值＝離子壓制
A14: RE%：萃取回收 | B14: =(B12/B11-1)*100 | C14: '=(B12/B11-1)*100 | D14: (C/B−1)×100
A15: PE%：流程效率 | B15: =(B12/B10-1)*100 | C15: '=(B12/B10-1)*100 | D15: (C/A−1)×100，整體流程效率
A17: 同位素內標（SIL-IS）面積比校正後，重跑三組實驗
A18: 項目 | B18: 結果 | C18: 公式 | D18: 說明
A19: 面積比斜率 A_IS（溶液標準） | B19: 1.02 | D19: 分析物/內標 面積比
A20: 面積比斜率 B_IS（萃取後添加） | B20: 0.98
A21: 面積比斜率 C_IS（添加後萃取） | B21: 0.972
A22: ME%_IS（補償後） | B22: =(B20/B19-1)*100 | C22: '=(B20/B19-1)*100 | D22: 從 −15.0% 縮到這個值
A23: RE%_IS（補償後） | B23: =(B21/B20-1)*100 | C23: '=(B21/B20-1)*100 | D23: 從 −9.9% 縮到這個值
A25: 殘餘基質效應（本例估 0.08）計入下一張工作表的不確定度預算「校正＋基質殘餘」項。

Sheet 加權迴歸1x
A1: 校正數據（與 R 檔 set.seed(11) 完全相同的教材數據）
A2: 濃度 conc (μg/kg) | B2: 面積比 ratio | C2: 權重 w=1/conc
A3: 0.02 | B3: 0.039328312 | C3: =1/A3
A4: 0.05 | B4: 0.10111893 | C4: =1/A4
A5: 0.1 | B5: 0.19140848 | C5: =1/A5
A6: 0.2 | B6: 0.38881206 | C6: =1/A6
A7: 0.5 | B7: 1.0176664 | C7: =1/A7
A9: ① 一般最小平方 OLS
A10: 項目 | B10: 結果 | C10: 公式 | D10: 說明
A11: b1_OLS：斜率 | B11: =SLOPE(B3:B7,A3:A7) | C11: '=SLOPE(B3:B7,A3:A7)
A12: b0_OLS：截距 | B12: =INTERCEPT(B3:B7,A3:A7) | C12: '=INTERCEPT(B3:B7,A3:A7)
A14: ② 1/x 加權迴歸（手刻加權最小平方，全部用 SUMPRODUCT）
A15: 項目 | B15: 結果 | C15: 公式 | D15: 說明
A16: x̄_w：加權平均濃度 | B16: =SUMPRODUCT(C3:C7,A3:A7)/SUM(C3:C7) | C16: '=SUMPRODUCT(C3:C7,A3:A7)/SUM(C3:C7) | D16: Σ(w·x)/Σw
A17: ȳ_w：加權平均面積比 | B17: =SUMPRODUCT(C3:C7,B3:B7)/SUM(C3:C7) | C17: '=SUMPRODUCT(C3:C7,B3:B7)/SUM(C3:C7) | D17: Σ(w·y)/Σw
A18: S_xy,w：加權交乘和 | B18: =SUMPRODUCT(C3:C7,(A3:A7-B16),(B3:B7-B17)) | C18: '=SUMPRODUCT(C3:C7,(A3:A7-B16),(B3:B7-B17)) | D18: Σw(x−x̄_w)(y−ȳ_w)——SUMPRODUCT 可以直接吃陣列運算，不用 Ctrl+Shift+Enter
A19: S_xx,w：加權平方和 | B19: =SUMPRODUCT(C3:C7,(A3:A7-B16)^2) | C19: '=SUMPRODUCT(C3:C7,(A3:A7-B16)^2) | D19: Σw(x−x̄_w)²
A20: b1_w：加權斜率 | B20: =B18/B19 | C20: '=B18/B19 | D20: S_xy,w / S_xx,w
A21: b0_w：加權截距 | B21: =B17-B20*B16 | C21: '=B17-B20*B16 | D21: ȳ_w − b1_w·x̄_w
A23: ③ 回算比較表（哪個方法在低濃度偏得少？）
A24: 名義濃度 | B24: 找回濃度_OLS | C24: OLS回算誤差% | D24: 找回濃度_加權 | E24: 加權回算誤差%
A25: =A3 | B25: =(B3-B12)/B11 | C25: =(B25/A25-1)*100 | D25: =(B3-B21)/B20 | E25: =(D25/A25-1)*100
A26: =A4 | B26: =(B4-B12)/B11 | C26: =(B26/A26-1)*100 | D26: =(B4-B21)/B20 | E26: =(D26/A26-1)*100
A27: =A5 | B27: =(B5-B12)/B11 | C27: =(B27/A27-1)*100 | D27: =(B5-B21)/B20 | E27: =(D27/A27-1)*100
A28: =A6 | B28: =(B6-B12)/B11 | C28: =(B28/A28-1)*100 | D28: =(B6-B21)/B20 | E28: =(D28/A28-1)*100
A29: =A7 | B29: =(B7-B12)/B11 | C29: =(B29/A29-1)*100 | D29: =(B7-B21)/B20 | E29: =(D29/A29-1)*100
A31: ④ 未知樣品反推（面積比 0.0405）
A32: 項目 | B32: 結果 | C32: 公式 | D32: 說明
A33: 未知樣品面積比 y_obs | B33: 0.0405
A34: 反推濃度（OLS） | B34: =(B33-B12)/B11 | C34: '=(B33-B12)/B11
A35: 反推濃度（1/x 加權） | B35: =(B33-B21)/B20 | C35: '=(B33-B21)/B20
A37: Monte Carlo 示範：加權反推濃度的變動範圍（F9 重算會變，不列入核對）
A38: 模擬編號 | B38: 模擬 y* | C38: 反推 x*（用固定 b1_w/b0_w 近似）
A39: 1 | B39: =_xlfn.NORM.INV(RAND(),B33,0.003) | C39: =(B39-B21)/B20
A40: 2 | B40: =_xlfn.NORM.INV(RAND(),B33,0.003) | C40: =(B40-B21)/B20
A41: 3 | B41: =_xlfn.NORM.INV(RAND(),B33,0.003) | C41: =(B41-B21)/B20
A42: 4 | B42: =_xlfn.NORM.INV(RAND(),B33,0.003) | C42: =(B42-B21)/B20
A43: 5 | B43: =_xlfn.NORM.INV(RAND(),B33,0.003) | C43: =(B43-B21)/B20
A44: 6 | B44: =_xlfn.NORM.INV(RAND(),B33,0.003) | C44: =(B44-B21)/B20
A45: 7 | B45: =_xlfn.NORM.INV(RAND(),B33,0.003) | C45: =(B45-B21)/B20
...

Sheet 不確定度預算與符合性
A1: 四個相對標準不確定度成分（內部驗證法，SANTE 風格）
A2: 來源 | B2: 數值 | C2: 分布 | D2: 除數 | E2: 標準不確定度 u | F2: 相對 u(x)/x | G2: u²占比 (%)
A3: 中間精密度 | B3: 1 | C3: 驗證期不同天/人/校正週期的樣品數據 | D3: — | E3: 0.22 | F3: =E3/1 | G3: =F3^2/B9^2*100
A4: 校正＋基質殘餘 | B4: 1 | C4: SIL-IS＋基質匹配校正後的殘餘基質效應 | D4: — | E4: 0.08 | F4: =E4/1 | G4: =F4^2/B9^2*100
A5: 回收率偏倚 | B5: 1 | C5: 加標回收平均 90%，平均值的標準誤 | D5: — | E5: 0.06 | F5: =E5/1 | G5: =F5^2/B9^2*100
A6: 樣品均勻性 | B6: 1 | C6: 痕量污染物在蝦肉組織的分布（最壞情境模型） | D6: — | E6: 0.15 | F6: =E6/1 | G6: =F6^2/B9^2*100
A8: 項目 | B8: 結果 | C8: 公式 | D8: 說明
A9: 相對合成不確定度 u_c(w)/w | B9: =SQRT(SUMSQ(F3,F4,F5,F6)) | C9: '=SQRT(SUMSQ(F3,F4,F5,F6)) | D9: 四項平方和開根號
A11: 儀器讀值（同位素稀釋，已扣除基質） (μg/kg) | B11: 0.19
A12: Rec：平均回收率 | B12: 0.9
A13: w：回收率修正後結果 (μg/kg) | B13: =B11/B12 | C13: '=B11/B12 | D13: raw / Rec
A14: U：擴展不確定度 (k=2, μg/kg) | B14: =2*B9*B13 | C14: '=2*B9*B13 | D14: 2 × 相對合成 × w
A15: 報告：氯黴素 = (0.21 ± 0.12) μg/kg（k=2）
A17: 符合性判定（保守決策規則）
A18: 項目 | B18: 結果 | C18: 公式 | D18: 說明
A19: MRPL：管制界限 (μg/kg) | B19: 0.3
A20: 下限 = w − U | B20: =B13-B14 | C20: '=B13-B14
A21: 上限 = w + U | B21: =B13+B14 | C21: '=B13+B14
A22: 判定 | B22: =IF(B20>B19,"不符合",IF(B21<=B19,"符合","灰色地帶")) | C22: '=IF(B20>B19,"不符合",IF(B21<=B19,"符合","灰色地帶")) | D22: 下限超過限量才判不符合；上限沒超過才判符合；其餘是灰色地帶
A24: Monte Carlo 決策支持示範：真值超過管制界限的機率（F9 重算會變，不列入核對）
A25: 模擬編號 | B25: 模擬真值 (μg/kg) | C25: 是否超標
A26: 1 | B26: =_xlfn.NORM.INV(RAND(),B13,B9*B13) | C26: =IF(B26>B19,1,0)
A27: 2 | B27: =_xlfn.NORM.INV(RAND(),B13,B9*B13) | C27: =IF(B27>B19,1,0)
A28: 3 | B28: =_xlfn.NORM.INV(RAND(),B13,B9*B13) | C28: =IF(B28>B19,1,0)
A29: 4 | B29: =_xlfn.NORM.INV(RAND(),B13,B9*B13) | C29: =IF(B29>B19,1,0)
A30: 5 | B30: =_xlfn.NORM.INV(RAND(),B13,B9*B13) | C30: =IF(B30>B19,1,0)
A31: 6 | B31: =_xlfn.NORM.INV(RAND(),B13,B9*B13) | C31: =IF(B31>B19,1,0)
A32: 7 | B32: =_xlfn.NORM.INV(RAND(),B13,B9*B13) | C32: =IF(B32>B19,1,0)
A33: 8 | B33: =_xlfn.NORM.INV(RAND(),B13,B9*B13) | C33: =IF(B33>B19,1,0)
A34: 9 | B34: =_xlfn.NORM.INV(RAND(),B13,B9*B13) | C34: =IF(B34>B19,1,0)
A35: 10 | B35: =_xlfn.NORM.INV(RAND(),B13,B9*B13) | C35: =IF(B35>B19,1,0)
A36: 11 | B36: =_xlfn.NORM.INV(RAND(),B13,B9*B13) | C36: =IF(B36>B19,1,0)
A37: 12 | B37: =_xlfn.NORM.INV(RAND(),B13,B9*B13) | C37: =IF(B37>B19,1,0)
A38: 13 | B38: =_xlfn.NORM.INV(RAND(),B13,B9*B13) | C38: =IF(B38>B19,1,0)
A39: 14 | B39: =_xlfn.NORM.INV(RAND(),B13,B9*B13) | C39: =IF(B39>B19,1,0)
A40: 15 | B40: =_xlfn.NORM.INV(RAND(),B13,B9*B13) | C40: =IF(B40>B19,1,0)
A41: 16 | B41: =_xlfn.NORM.INV(RAND(),B13,B9*B13) | C41: =IF(B41>B19,1,0)
A42: 17 | B42: =_xlfn.NORM.INV(RAND(),B13,B9*B13) | C42: =IF(B42>B19,1,0)
A43: 18 | B43: =_xlfn.NORM.INV(RAND(),B13,B9*B13) | C43: =IF(B43>B19,1,0)
A44: 19 | B44: =_xlfn.NORM.INV(RAND(),B13,B9*B13) | C44: =IF(B44>B19,1,0)
...

Sheet 對照R答案
A1: 項目 | B1: Excel 算出來 | C1: R 的答案 | D1: 一致？ | E1: 來源儲存格
A2: Matuszewski 斜率 A | B2: ='Matuszewski基質效應'!B10 | C2: 45200 | D2: =IF(ABS(B2-C2)<=22.6,"✓","✗") | E2: 'Matuszewski基質效應'!B10
A3: ME%（基質效應） | B3: ='Matuszewski基質效應'!B13 | C3: -15.044248 | D3: =IF(ABS(B3-C3)<=0.007522123895,"✓","✗") | E3: 'Matuszewski基質效應'!B13
A4: RE%（萃取回收） | B4: ='Matuszewski基質效應'!B14 | C4: -9.8958333 | D4: =IF(ABS(B4-C4)<=0.0049479166665,"✓","✗") | E4: 'Matuszewski基質效應'!B14
A5: PE%（流程效率） | B5: ='Matuszewski基質效應'!B15 | C5: -23.451327 | D5: =IF(ABS(B5-C5)<=0.011725663715,"✓","✗") | E5: 'Matuszewski基質效應'!B15
A6: ME%_IS（補償後） | B6: ='Matuszewski基質效應'!B22 | C6: -3.9215686 | D6: =IF(ABS(B6-C6)<=0.0019607843135,"✓","✗") | E6: 'Matuszewski基質效應'!B22
A7: RE%_IS（補償後） | B7: ='Matuszewski基質效應'!B23 | C7: -0.81632653 | D7: =IF(ABS(B7-C7)<=0.00040816326530000003,"✓","✗") | E7: 'Matuszewski基質效應'!B23
A8: OLS 斜率 b1 | B8: ='加權迴歸1x'!B11 | C8: 2.0400529 | D8: =IF(ABS(B8-C8)<=0.001020026431347,"✓","✗") | E8: '加權迴歸1x'!B11
A9: OLS 截距 b0 | B9: ='加權迴歸1x'!B12 | C9: -0.0073023716 | D9: =IF(ABS(B9-C9)<=3.651185787e-06,"✓","✗") | E9: '加權迴歸1x'!B12
A10: 加權斜率 b1_w | B10: ='加權迴歸1x'!B20 | C10: 2.0087534 | D10: =IF(ABS(B10-C10)<=0.0010043766965,"✓","✗") | E10: '加權迴歸1x'!B20
A11: 加權截距 b0_w | B11: ='加權迴歸1x'!B21 | C11: -0.0018562639 | D11: =IF(ABS(B11-C11)<=9.281319299999999e-07,"✓","✗") | E11: '加權迴歸1x'!B21
A12: 反推濃度（1/x 加權） | B12: ='加權迴歸1x'!B35 | C12: 0.021085846 | D12: =IF(ABS(B12-C12)<=1.054292279e-05,"✓","✗") | E12: '加權迴歸1x'!B35
A13: 找回濃度_加權 (conc=0.02) | B13: ='加權迴歸1x'!D25 | C13: 0.020502554 | D13: =IF(ABS(B13-C13)<=1.0251277135000001e-05,"✓","✗") | E13: '加權迴歸1x'!D25
A14: LC-MS/MS 相對合成不確定度 | B14: ='不確定度預算與符合性'!B9 | C14: 0.28442925 | D14: =IF(ABS(B14-C14)<=0.00014221462655,"✓","✗") | E14: '不確定度預算與符合性'!B9
A15: LC-MS/MS 結果 w | B15: ='不確定度預算與符合性'!B13 | C15: 0.21111111 | D15: =IF(ABS(B15-C15)<=0.00010555555555000001,"✓","✗") | E15: '不確定度預算與符合性'!B13
A16: LC-MS/MS U (k=2) | B16: ='不確定度預算與符合性'!B14 | C16: 0.12009235 | D16: =IF(ABS(B16-C16)<=6.004617565e-05,"✓","✗") | E16: '不確定度預算與符合性'!B14
A18: 如果你改了黃色儲存格的數據，這裡當然會變成 ✗——那是因為 R 的答案是用原始教材數據算的。
