Workbook

Sheet 說明
A1: Ch14 DOE/RSM：2^3 因子效應、曲率檢定、CCD 二階模型
A2: 對應網頁：ch14.html ｜ 黃色儲存格＝可以改成你自己的數據；其他是公式，請不要直接覆蓋。
A4: 這本活頁簿在做什麼
A5: 情境：超音波輔助萃取茶葉多酚，反應值＝DPPH 清除率(%)。因子：A 乙醇濃度、B 萃取溫度、C 超音波時間（都用 ±1 編碼）。
A6: 「2^3因子設計」用 8 個角落點＋4 個中心點，算出主效應、交互作用，並用中心點做「曲率檢定」（反應曲面是不是彎的）。
A7: 「CCD二階模型」在 8 角落點外加 6 個軸點＋6 個中心點（共 20 run），配二階（含平方項）模型，算出某條件下的預測值、殘差 SS、中心點純誤差 SS，以及失擬檢定（模型夠不夠用）。
A8: 怎麼用
A9: 1. 「2^3因子設計」左邊黃色是編碼 A/B/C 與實測 y；右邊先算 6 個效應（A、B、C、AB、AC、BC），再做曲率檢定。
A10: 2. 「CCD二階模型」用 LINEST 一次配出 10 個係數（用 INDEX 逐一取值）；下面「預測條件」區塊的 a/b/c 是黃格，改了就能看模型怎麼預測不同條件下的清除率。
A11: 3. 試著把中心點的某個 y 改得離群一點，看純誤差 SS 變大、失擬檢定的 F 變小（模型看起來「更夠用」，這其實是假象，要小心解讀）。
A12: 4. 「對照R答案」核對所有關鍵結果。
A13: 觀念提醒
... A23: ⑤ 工具箱的迴歸輸出是靜態表；本活頁簿用 LINEST／INDEX 寫成公式，改黃色數據會自動重算。

Sheet 2^3因子設計
A1: A(乙醇) | B1: B(溫度) | C1: C(時間) | D1: AB | E1: AC | F1: BC | G1: y(DPPH%)
A2: -1 | B2: -1 | C2: -1 | D2: =A2*B2 | E2: =A2*C2 | F2: =B2*C2 | G2: 33.7
A3: 1 | B3: -1 | C3: -1 | D3: =A3*B3 | E3: =A3*C3 | F3: =B3*C3 | G3: 41.6
A4: -1 | B4: 1 | C4: -1 | D4: =A4*B4 | E4: =A4*C4 | F4: =B4*C4 | G4: 38
A5: 1 | B5: 1 | C5: -1 | D5: =A5*B5 | E5: =A5*C5 | F5: =B5*C5 | G5: 52.3
A6: -1 | B6: -1 | C6: 1 | D6: =A6*B6 | E6: =A6*C6 | F6: =B6*C6 | G6: 38.5
A7: 1 | B7: -1 | C7: 1 | D7: =A7*B7 | E7: =A7*C7 | F7: =B7*C7 | G7: 45
A8: -1 | B8: 1 | C8: 1 | D8: =A8*B8 | E8: =A8*C8 | F8: =B8*C8 | G8: 39.4
A9: 1 | B9: 1 | C9: 1 | D9: =A9*B9 | E9: =A9*C9 | F9: =B9*C9 | G9: 55.8
A11: 中心點 y（A=B=C=0，4 次獨立重複萃取）
A12: 59.5
A13: 61.3
A14: 59.5
A15: 60.4
A18: 項目 | B18: 結果 | C18: 公式 | D18: 白話說明
A19: 對比 contrast_A | B19: =SUMPRODUCT(A2:A9,G2:G9) | C19: '=SUMPRODUCT(A2:A9,G2:G9) | D19: Σ(A欄 × y)
A20: 效應 effect_A | B20: =B19/4 | C20: '=B19/4 | D20: 對比 ÷ (N/2) = 對比 ÷ 4（N=8）
A21: 係數 coef_A | B21: =B20/2 | C21: '=B20/2 | D21: 效應的一半
A22: 對比 contrast_B | B22: =SUMPRODUCT(B2:B9,G2:G9) | C22: '=SUMPRODUCT(B2:B9,G2:G9)
A23: 效應 effect_B | B23: =B22/4 | C23: '=B22/4
A24: 係數 coef_B | B24: =B23/2 | C24: '=B23/2
A25: 對比 contrast_C | B25: =SUMPRODUCT(C2:C9,G2:G9) | C25: '=SUMPRODUCT(C2:C9,G2:G9)
A26: 效應 effect_C | B26: =B25/4 | C26: '=B25/4
A27: 係數 coef_C | B27: =B26/2 | C27: '=B26/2
A28: 對比 contrast_AB | B28: =SUMPRODUCT(D2:D9,G2:G9) | C28: '=SUMPRODUCT(D2:D9,G2:G9)
A29: 效應 effect_AB（交互作用） | B29: =B28/4 | C29: '=B28/4
A30: 係數 coef_AB | B30: =B29/2 | C30: '=B29/2
A31: 對比 contrast_AC | B31: =SUMPRODUCT(E2:E9,G2:G9) | C31: '=SUMPRODUCT(E2:E9,G2:G9)
A32: 效應 effect_AC | B32: =B31/4 | C32: '=B31/4
A33: 對比 contrast_BC | B33: =SUMPRODUCT(F2:F9,G2:G9) | C33: '=SUMPRODUCT(F2:F9,G2:G9)
A34: 效應 effect_BC | B34: =B33/4 | C34: '=B33/4
A36: 曲率檢定：中心點平均 vs 因子點平均
A37: 因子點平均 | B37: =AVERAGE(G2:G9) | C37: '=AVERAGE(G2:G9)
A38: 中心點平均 | B38: =AVERAGE(A12:A15) | C38: '=AVERAGE(A12:A15)
A39: 純誤差 s_pure | B39: =_xlfn.STDEV.S(A12:A15) | C39: '=STDEV.S(A12:A15) | D39: 只有中心點重複能給出的誤差估計
A40: 曲率 t 值 | B40: =(B38-B37)/(B39*SQRT(1/4+1/8)) | C40: '=(B38-B37)/(B39*SQRT(1/4+1/8))
A41: 曲率 p 值（雙尾） | B41: =_xlfn.T.DIST.2T(ABS(B40),3) | C41: '=T.DIST.2T(ABS(B40),3) | D41: H0：中心點平均＝因子點平均（曲面沒有彎）
A43: p 值極小 → 反應曲面是彎的，直線模型不夠用，需要升級到 CCD（見「CCD二階模型」）。

Sheet CCD二階模型
A1: A | B1: B | C1: C | D1: A² | E1: B² | F1: C² | G1: AB | H1: AC | I1: BC | J1: y(DPPH%) | K1: ŷ（模型預測） | L1: 殘差 y−ŷ
A2: -1 | B2: -1 | C2: -1 | D2: =A2^2 | E2: =B2^2 | F2: =C2^2 | G2: =A2*B2 | H2: =A2*C2 | I2: =B2*C2 | J2: 34.8 | K2: =$B$24+A2*$B$25+B2*$B$26+C2*$B$27+D2*$B$28+E2*$B$29+F2*$B$30+G2*$B$31+H2*$B$32+I2*$B$33 | L2: =J2-K2
A3: 1 | B3: -1 | C3: -1 | D3: =A3^2 | E3: =B3^2 | F3: =C3^2 | G3: =A3*B3 | H3: =A3*C3 | I3: =B3*C3 | J3: 41.7 | K3: =$B$24+A3*$B$25+B3*$B$26+C3*$B$27+D3*$B$28+E3*$B$29+F3*$B$30+G3*$B$31+H3*$B$32+I3*$B$33 | L3: =J3-K3
A4: -1 | B4: 1 | C4: -1 | D4: =A4^2 | E4: =B4^2 | F4: =C4^2 | G4: =A4*B4 | H4: =A4*C4 | I4: =B4*C4 | J4: 35.1 | K4: =$B$24+A4*$B$25+B4*$B$26+C4*$B$27+D4*$B$28+E4*$B$29+F4*$B$30+G4*$B$31+H4*$B$32+I4*$B$33 | L4: =J4-K4
A5: 1 | B5: 1 | C5: -1 | D5: =A5^2 | E5: =B5^2 | F5: =C5^2 | G5: =A5*B5 | H5: =A5*C5 | I5: =B5*C5 | J5: 51.6 | K5: =$B$24+A5*$B$25+B5*$B$26+C5*$B$27+D5*$B$28+E5*$B$29+F5*$B$30+G5*$B$31+H5*$B$32+I5*$B$33 | L5: =J5-K5
A6: -1 | B6: -1 | C6: 1 | D6: =A6^2 | E6: =B6^2 | F6: =C6^2 | G6: =A6*B6 | H6: =A6*C6 | I6: =B6*C6 | J6: 39.1 | K6: =$B$24+A6*$B$25+B6*$B$26+C6*$B$27+D6*$B$28+E6*$B$29+F6*$B$30+G6*$B$31+H6*$B$32+I6*$B$33 | L6: =J6-K6
A7: 1 | B7: -1 | C7: 1 | D7: =A7^2 | E7: =B7^2 | F7: =C7^2 | G7: =A7*B7 | H7: =A7*C7 | I7: =B7*C7 | J7: 42 | K7: =$B$24+A7*$B$25+B7*$B$26+C7*$B$27+D7*$B$28+E7*$B$29+F7*$B$30+G7*$B$31+H7*$B$32+I7*$B$33 | L7: =J7-K7
A8: -1 | B8: 1 | C8: 1 | D8: =A8^2 | E8: =B8^2 | F8: =C8^2 | G8: =A8*B8 | H8: =A8*C8 | I8: =B8*C8 | J8: 39.5 | K8: =$B$24+A8*$B$25+B8*$B$26+C8*$B$27+D8*$B$28+E8*$B$29+F8*$B$30+G8*$B$31+H8*$B$32+I8*$B$33 | L8: =J8-K8
A9: 1 | B9: 1 | C9: 1 | D9: =A9^2 | E9: =B9^2 | F9: =C9^2 | G9: =A9*B9 | H9: =A9*C9 | I9: =B9*C9 | J9: 55.8 | K9: =$B$24+A9*$B$25+B9*$B$26+C9*$B$27+D9*$B$28+E9*$B$29+F9*$B$30+G9*$B$31+H9*$B$32+I9*$B$33 | L9: =J9-K9
A10: -1.6817928 | B10: 0 | C10: 0 | D10: =A10^2 | E10: =B10^2 | F10: =C10^2 | G10: =A10*B10 | H10: =A10*C10 | I10: =B10*C10 | J10: 31.6 | K10: =$B$24+A10*$B$25+B10*$B$26+C10*$B$27+D10*$B$28+E10*$B$29+F10*$B$30+G10*$B$31+H10*$B$32+I10*$B$33 | L10: =J10-K10
A11: 1.6817928 | B11: 0 | C11: 0 | D11: =A11^2 | E11: =B11^2 | F11: =C11^2 | G11: =A11*B11 | H11: =A11*C11 | I11: =B11*C11 | J11: 47.3 | K11: =$B$24+A11*$B$25+B11*$B$26+C11*$B$27+D11*$B$28+E11*$B$29+F11*$B$30+G11*$B$31+H11*$B$32+I11*$B$33 | L11: =J11-K11
A12: 0 | B12: -1.6817928 | C12: 0 | D12: =A12^2 | E12: =B12^2 | F12: =C12^2 | G12: =A12*B12 | H12: =A12*C12 | I12: =B12*C12 | J12: 41.8 | K12: =$B$24+A12*$B$25+B12*$B$26+C12*$B$27+D12*$B$28+E12*$B$29+F12*$B$30+G12*$B$31+H12*$B$32+I12*$B$33 | L12: =J12-K12
A13: 0 | B13: 1.6817928 | C13: 0 | D13: =A13^2 | E13: =B13^2 | F13: =C13^2 | G13: =A13*B13 | H13: =A13*C13 | I13: =B13*C13 | J13: 50.5 | K13: =$B$24+A13*$B$25+B13*$B$26+C13*$B$27+D13*$B$28+E13*$B$29+F13*$B$30+G13*$B$31+H13*$B$32+I13*$B$33 | L13: =J13-K13
... A21: 0 | B21: 0 | C21: 0 | D21: =A21^2 | E21: =B21^2 | F21: =C21^2 | G21: =A21*B21 | H21: =A21*C21 | I21: =B21*C21 | J21: 59.4 | K21: =$B$24+A21*$B$25+B21*$B$26+C21*$B$27+D21*$B$28+E21*$B$29+F21*$B$30+G21*$B$31+H21*$B$32+I21*$B$33 | L21: =J21-K21
A23: 係數（LINEST） | B23: 值 | C23: 公式 | D23: 白話說明
A24: Intercept | B24: =INDEX(LINEST(J2:J21,A2:I21),1,10) | C24: '=INDEX(LINEST(J2:J21,A2:I21),1,10) | D24: LINEST 係數順序與 X 欄位相反：截距永遠是最後一個
A25: coef_A | B25: =INDEX(LINEST(J2:J21,A2:I21),1,9) | C25: '=INDEX(LINEST(J2:J21,A2:I21),1,9) | D25: X 第1欄(A)的係數在陣列倒數第2位
A26: coef_B | B26: =INDEX(LINEST(J2:J21,A2:I21),1,8) | C26: '=INDEX(LINEST(J2:J21,A2:I21),1,8)
A27: coef_C | B27: =INDEX(LINEST(J2:J21,A2:I21),1,7) | C27: '=INDEX(LINEST(J2:J21,A2:I21),1,7)
A28: coef_A² | B28: =INDEX(LINEST(J2:J21,A2:I21),1,6) | C28: '=INDEX(LINEST(J2:J21,A2:I21),1,6)
A29: coef_B² | B29: =INDEX(LINEST(J2:J21,A2:I21),1,5) | C29: '=INDEX(LINEST(J2:J21,A2:I21),1,5)
A30: coef_C² | B30: =INDEX(LINEST(J2:J21,A2:I21),1,4) | C30: '=INDEX(LINEST(J2:J21,A2:I21),1,4)
A31: coef_AB | B31: =INDEX(LINEST(J2:J21,A2:I21),1,3) | C31: '=INDEX(LINEST(J2:J21,A2:I21),1,3)
A32: coef_AC | B32: =INDEX(LINEST(J2:J21,A2:I21),1,2) | C32: '=INDEX(LINEST(J2:J21,A2:I21),1,2)
A33: coef_BC | B33: =INDEX(LINEST(J2:J21,A2:I21),1,1) | C33: '=INDEX(LINEST(J2:J21,A2:I21),1,1) | D33: X 最後一欄(BC)的係數在陣列第1位
A35: 殘差、純誤差與失擬檢定
A36: 項目 | B36: 結果 | C36: 公式 | D36: 白話說明
A37: 殘差 SS | B37: =SUMSQ(L2:L21) | C37: '=SUMSQ(L2:L21) | D37: 模型 ŷ 與實測 y 的差，逐列平方加總
A38: 中心點純誤差 SS | B38: =DEVSQ(J16:J21) | C38: '=DEVSQ(J16:J21) | D38: 只有 6 個中心點重複能提供純誤差（df=5）
A39: 失擬 SS | B39: =B37-B38 | C39: '=B37-B38
A40: df_殘差 | B40: =20-10 | C40: '=20-10 | D40: 20 個 run − 10 個模型參數
A41: df_純誤差 | B41: =6-1 | C41: '=6-1 | D41: 6 個中心點
A42: df_失擬 | B42: =B40-B41 | C42: '=B40-B41
A43: F（失擬檢定） | B43: =(B39/B42)/(B38/B41) | C43: '=(B39/B42)/(B38/B41)
A44: p 值 | B44: =_xlfn.F.DIST.RT(B43,B42,B41) | C44: '=F.DIST.RT(B43,B42,B41) | D44: p 大才好：不顯著＝在純誤差的尺度下看不出模型不足
A46: 在特定條件下用二階模型預測（a/b/c 是黃格，可以改）
A47: 項目 | B47: 結果 | C47: 公式 | D47: 白話說明
A48: a（A 編碼，預設＝駐點） | B48: 0.44256929
A49: b（B 編碼，預設＝駐點） | B49: 0.44546401
A50: c（C 編碼，預設＝駐點） | B50: 0.13029468
...

Sheet 對照R答案
A1: 項目 | B1: Excel 算出來 | C1: R 的答案 | D1: 一致？ | E1: 來源儲存格
A2: 2^3：效應 effect_A | B2: ='2^3因子設計'!B20 | C2: 11.275 | D2: =IF(ABS(B2-C2)<=0.0056375,"✓","✗") | E2: '2^3因子設計'!B20
A3: 2^3：效應 effect_B | B3: ='2^3因子設計'!B23 | C3: 6.675 | D3: =IF(ABS(B3-C3)<=0.0033375,"✓","✗") | E3: '2^3因子設計'!B23
A4: 2^3：效應 effect_AB | B4: ='2^3因子設計'!B29 | C4: 4.075 | D4: =IF(ABS(B4-C4)<=0.0020375000000000002,"✓","✗") | E4: '2^3因子設計'!B29
A5: 2^3：曲率 t 值 | B5: ='2^3因子設計'!B40 | C5: 32.477576 | D5: =IF(ABS(B5-C5)<=0.016238787895000002,"✓","✗") | E5: '2^3因子設計'!B40
A6: 2^3：曲率 p 值 | B6: ='2^3因子設計'!B41 | C6: 6.4156353e-05 | D6: =IF(ABS(B6-C6)<=1e-09,"✓","✗") | E6: '2^3因子設計'!B41
A7: CCD：Intercept | B7: ='CCD二階模型'!B24 | C7: 59.939778 | D7: =IF(ABS(B7-C7)<=0.029969889045500003,"✓","✗") | E7: 'CCD二階模型'!B24
A8: CCD：coef_A | B8: ='CCD二階模型'!B25 | C8: 5.0527117 | D8: =IF(ABS(B8-C8)<=0.002526355857,"✓","✗") | E8: 'CCD二階模型'!B25
A9: CCD：coef_BC | B9: ='CCD二階模型'!B33 | C9: 0.5 | D9: =IF(ABS(B9-C9)<=0.00025,"✓","✗") | E9: 'CCD二階模型'!B33
A10: CCD：預測 ŷ0（駐點） | B10: ='CCD二階模型'!B57 | C10: 61.79752 | D10: =IF(ABS(B10-C10)<=0.030898760015000002,"✓","✗") | E10: 'CCD二階模型'!B57
A11: CCD：殘差 SS | B11: ='CCD二階模型'!B37 | C11: 11.805444 | D11: =IF(ABS(B11-C11)<=0.005902722190000001,"✓","✗") | E11: 'CCD二階模型'!B37
A12: CCD：純誤差 SS | B12: ='CCD二階模型'!B38 | C12: 5.5533333 | D12: =IF(ABS(B12-C12)<=0.0027766666665000003,"✓","✗") | E12: 'CCD二階模型'!B38
A13: CCD：失擬 SS | B13: ='CCD二階模型'!B39 | C13: 6.252111 | D13: =IF(ABS(B13-C13)<=0.003126055523,"✓","✗") | E13: 'CCD二階模型'!B39
A14: CCD：F（失擬） | B14: ='CCD二階模型'!B43 | C14: 1.1258303 | D14: =IF(ABS(B14-C14)<=0.00056291516,"✓","✗") | E14: 'CCD二階模型'!B43
A15: CCD：p（失擬） | B15: ='CCD二階模型'!B44 | C15: 0.44984497 | D15: =IF(ABS(B15-C15)<=0.0002249224845,"✓","✗") | E15: 'CCD二階模型'!B44
A17: 如果你改了黃色儲存格的數據，這裡當然會變成 ✗——那是因為 R 的答案是用原始教材數據算的。
