Workbook

Sheet 說明
A1: Ch17 ANOVA 進階：雙因子、精密度分解、失擬檢定
A2: 對應網頁：ch17.html ｜ 黃色儲存格＝可以改成你自己的數據；其他是公式，請不要直接覆蓋。
A4: 這本活頁簿在做什麼
A5: 三張計算表對應本章三個主題：「雙因子ANOVA」拆出溫度、時間與交互作用的效應（芭樂片乾燥維生素C保留率）；「ISO5725精密度分解」把日間、日內變異從一張單因子 ANOVA 表拆成重複性 s_r 與中間精密度 s_I（奶粉QC）；「失擬檢定」檢查 HPLC 咖啡因標準曲線是不是真的直（純誤差 vs 失擬）。
A6: 怎麼用
A7: 1. 「雙因子ANOVA」左邊黃色是 3 溫度 × 2 時間 × 3 重複＝18 筆數據；右邊照 SS_A（溫度）→SS_B（時間）→SS_AB（交互作用）→SS_error 的順序拆開算。
A8: 2. 「ISO5725精密度分解」試著把某一天的三個數值改得很接近，看 s_between 會不會變成需要 MAX(0,…) 保護的負值。
A9: 3. 「失擬檢定」把任一濃度的三個重複值改得很分散，看純誤差 SS 變大、F 變小、p 變大（模型看起來更「夠用」，但那是假象——一定要同時看殘差圖）。
A10: 4. 「對照R答案」核對所有關鍵結果。
A11: 觀念提醒
A12: ① 雙因子 ANOVA 交互作用顯著時，主效應（單獨看溫度或時間）沒有意義，要看每個溫度下時間的效應（simple effects）。
A13: ② s_between² 算出負值不是算錯，是日間變異真的很小時的正常抽樣結果，慣例取 0（Excel 用 MAX(0,…) 處理）。
... A21: ⑥ 工具箱輸出一律是靜態表，改數據要重新跑一次「資料分析」；本活頁簿的公式版會自動重算。

Sheet 雙因子ANOVA
A1: 溫度(°C) | B1: 4h 保留率(%) | C1: 8h 保留率(%)
A2: 50 | B2: 90.5 | C2: 88.5
A3: 50 | B3: 91.9 | C3: 89.8
A4: 50 | B4: 91.7 | C4: 89
A5: 60 | B5: 83.8 | C5: 77.9
A6: 60 | B6: 86.2 | C6: 76.3
A7: 60 | B7: 84.8 | C7: 78.4
A8: 70 | B8: 75.5 | C8: 54.9
A9: 70 | B9: 76.6 | C9: 56.3
A10: 70 | B10: 74.4 | C10: 55.2
A12: 項目 | B12: 結果 | C12: 公式 | D12: 白話說明
A13: 總平均 grand mean | B13: =AVERAGE(B2:C10) | C13: '=AVERAGE(B2:C10)
A14: 溫度平均 50°C | B14: =(AVERAGEIF(A2:A10,50,B2:B10)+AVERAGEIF(A2:A10,50,C2:C10))/2 | C14: '=(AVERAGEIF(A2:A10,50,B2:B10)+AVERAGEIF(A2:A10,50,C2:C10))/2 | D14: 同一溫度下 4h、8h 兩欄各自平均再平均（各 3 筆，等重）
A15: 溫度平均 60°C | B15: =(AVERAGEIF(A2:A10,60,B2:B10)+AVERAGEIF(A2:A10,60,C2:C10))/2 | C15: '=(AVERAGEIF(A2:A10,60,B2:B10)+AVERAGEIF(A2:A10,60,C2:C10))/2
A16: 溫度平均 70°C | B16: =(AVERAGEIF(A2:A10,70,B2:B10)+AVERAGEIF(A2:A10,70,C2:C10))/2 | C16: '=(AVERAGEIF(A2:A10,70,B2:B10)+AVERAGEIF(A2:A10,70,C2:C10))/2
A17: 時間平均 4h | B17: =AVERAGE(B2:B10) | C17: '=AVERAGE(B2:B10) | D17: 4h 欄本身就橫跨三個溫度，直接平均即為時間的邊際平均
A18: 時間平均 8h | B18: =AVERAGE(C2:C10) | C18: '=AVERAGE(C2:C10)
A19: 格平均 50°C×4h | B19: =AVERAGEIF(A2:A10,50,B2:B10) | C19: '=AVERAGEIF(A2:A10,50,B2:B10)
A20: 格平均 50°C×8h | B20: =AVERAGEIF(A2:A10,50,C2:C10) | C20: '=AVERAGEIF(A2:A10,50,C2:C10)
A21: 格平均 60°C×4h | B21: =AVERAGEIF(A2:A10,60,B2:B10) | C21: '=AVERAGEIF(A2:A10,60,B2:B10)
A22: 格平均 60°C×8h | B22: =AVERAGEIF(A2:A10,60,C2:C10) | C22: '=AVERAGEIF(A2:A10,60,C2:C10)
A23: 格平均 70°C×4h | B23: =AVERAGEIF(A2:A10,70,B2:B10) | C23: '=AVERAGEIF(A2:A10,70,B2:B10)
A24: 格平均 70°C×8h | B24: =AVERAGEIF(A2:A10,70,C2:C10) | C24: '=AVERAGEIF(A2:A10,70,C2:C10)
A26: SS_total | B26: =DEVSQ(B2:C10) | C26: '=DEVSQ(B2:C10)
A27: SS_cells（各格平均離總平均，×n=3） | B27: =3*((B19-B13)^2+(B20-B13)^2+(B21-B13)^2+(B22-B13)^2+(B23-B13)^2+(B24-B13)^2) | C27: '=3*((B19-B13)^2+(B20-B13)^2+(B21-B13)^2+(B22-B13)^2+(B23-B13)^2+(B24-B13)^2)
A28: SS_A（溫度）＝b×n×Σ(溫度平均−總平均)²，b=2,n=3 | B28: =6*((B14-B13)^2+(B15-B13)^2+(B16-B13)^2) | C28: '=6*((B14-B13)^2+(B15-B13)^2+(B16-B13)^2)
A29: SS_B（時間）＝a×n×Σ(時間平均−總平均)²，a=3,n=3 | B29: =9*((B17-B13)^2+(B18-B13)^2) | C29: '=9*((B17-B13)^2+(B18-B13)^2)
A30: SS_AB（交互作用）＝SS_cells−SS_A−SS_B | B30: =B27-B28-B29 | C30: '=B27-B28-B29
A31: SS_error＝SS_total−SS_cells | B31: =B26-B27 | C31: '=B26-B27
A32: df_A | B32: 2
A33: df_B | B33: 1
A34: df_AB | B34: 2
A35: df_error | B35: =COUNT(B2:C10)-6 | C35: '=COUNT(B2:C10)-6 | D35: 18筆 − 6格 = 12
A36: MS_A | B36: =B28/B32 | C36: '=B28/B32
A37: MS_B | B37: =B29/B33 | C37: '=B29/B33
A38: MS_AB | B38: =B30/B34 | C38: '=B30/B34
A39: MS_error | B39: =B31/B35 | C39: '=B31/B35
A40: F_A（溫度） | B40: =B36/B39 | C40: '=B36/B39
A41: F_B（時間） | B41: =B37/B39 | C41: '=B37/B39
A42: F_AB（交互作用） | B42: =B38/B39 | C42: '=B38/B39
...

Sheet ISO5725精密度分解
A1: day1 | B1: day2 | C1: day3 | D1: day4 | E1: day5
A2: 26.45 | B2: 26.52 | C2: 26.4 | D2: 26.27 | E2: 26.57
A3: 26.35 | B3: 26.46 | C3: 26.49 | D3: 26.26 | E3: 26.56
A4: 26.57 | B4: 26.7 | C4: 26.59 | D4: 26.33 | E4: 26.44
A6: 項目 | B6: 結果 | C6: 公式 | D6: 白話說明
A7: 日平均 day1 | B7: =AVERAGE(A2:A4) | C7: '=AVERAGE(A2:A4)
A8: 日平均 day2 | B8: =AVERAGE(B2:B4) | C8: '=AVERAGE(B2:B4)
A9: 日平均 day3 | B9: =AVERAGE(C2:C4) | C9: '=AVERAGE(C2:C4)
A10: 日平均 day4 | B10: =AVERAGE(D2:D4) | C10: '=AVERAGE(D2:D4)
A11: 日平均 day5 | B11: =AVERAGE(E2:E4) | C11: '=AVERAGE(E2:E4)
A12: 總平均 | B12: =AVERAGE(A2:E4) | C12: '=AVERAGE(A2:E4)
A13: SS_between（日間） | B13: =3*((B7-B12)^2+(B8-B12)^2+(B9-B12)^2+(B10-B12)^2+(B11-B12)^2) | C13: '=3*((B7-B12)^2+(B8-B12)^2+(B9-B12)^2+(B10-B12)^2+(B11-B12)^2)
A14: SS_within（日內） | B14: =DEVSQ(A2:A4)+DEVSQ(B2:B4)+DEVSQ(C2:C4)+DEVSQ(D2:D4)+DEVSQ(E2:E4) | C14: '=DEVSQ(A2:A4)+DEVSQ(B2:B4)+DEVSQ(C2:C4)+DEVSQ(D2:D4)+DEVSQ(E2:E4)
A15: df_between | B15: 4
A16: df_within | B16: 10
A17: MS_between | B17: =B13/B15 | C17: '=B13/B15
A18: MS_within | B18: =B14/B16 | C18: '=B14/B16
A19: 重複性 s_r | B19: =SQRT(B18) | C19: '=SQRT(B18) | D19: 即 √MS_within
A20: 日間 s_between | B20: =SQRT(MAX(0,(B17-B18)/3)) | C20: '=SQRT(MAX(0,(B17-B18)/3)) | D20: MAX(0,…) 處理負值；3=每天重複數
A21: 中間精密度 s_I | B21: =SQRT(SUMSQ(B19,B20)) | C21: '=SQRT(SUMSQ(B19,B20)) | D21: 即 √(s_r² + s_between²)
A22: ✗ 對照：全部15格直接 STDEV.S | B22: =_xlfn.STDEV.S(A2:E4) | C22: '=STDEV.S(A2:E4) | D22: 既不是 s_r 也不是 s_I，是日間日內混在一起的值
A23: ✗ 只用當天重複算 SE（低估） | B23: =B19/SQRT(3) | C23: '=B19/SQRT(3) | D23: 忽略了日間變異，會低估「單天平均值」真正的不確定度
A24: ✓ 正確：當天平均值的不確定度 | B24: =SQRT(SUMSQ(B20,B23)) | C24: '=SQRT(SUMSQ(B20,B23)) | D24: 日間變異不會因為多測幾次而變小
A26: s_I 一定 ≥ s_r（多了日間這個變異來源）；把 15 筆數據直接丟進 STDEV.S 得到的既不是 s_r 也不是 s_I，是兩者按自由度混合的值。

Sheet 失擬檢定
A1: 濃度 (mg/L) | B1: 波峰面積
A2: 1 | B2: 101
A3: 1 | B3: 99
A4: 1 | B4: 102
A5: 5 | B5: 498
A6: 5 | B6: 505
A7: 5 | B7: 492
A8: 10 | B8: 1005
A9: 10 | B9: 992
A10: 10 | B10: 1018
A11: 50 | B11: 4930
A12: 50 | B12: 5070
A13: 50 | B13: 5005
... A16: 100 | B16: 10040
A18: 項目 | B18: 結果 | C18: 公式 | D18: 白話說明
A19: 斜率 slope | B19: =SLOPE(B2:B16,A2:A16) | C19: '=SLOPE(B2:B16,A2:A16)
A20: 截距 intercept | B20: =INTERCEPT(B2:B16,A2:A16) | C20: '=INTERCEPT(B2:B16,A2:A16)
A21: r² | B21: =RSQ(B2:B16,A2:A16) | C21: '=RSQ(B2:B16,A2:A16) | D21: 很高，看起來「很直」
A22: 殘差 SS（直線模型） | B22: =DEVSQ(B2:B16)*(1-RSQ(B2:B16,A2:A16)) | C22: '=DEVSQ(B2:B16)*(1-RSQ(B2:B16,A2:A16)) | D22: 即 SS_total,y × (1−r²)；也可用「資料分析→迴歸」輸出的殘差 SS 對照
A23: 純誤差 SS | B23: =DEVSQ(B2:B4)+DEVSQ(B5:B7)+DEVSQ(B8:B10)+DEVSQ(B11:B13)+DEVSQ(B14:B16) | C23: '=DEVSQ(B2:B4)+DEVSQ(B5:B7)+DEVSQ(B8:B10)+DEVSQ(B11:B13)+DEVSQ(B14:B16) | D23: 每個濃度各算一次 DEVSQ 再相加：重複點離「自己濃度平均」多遠
A24: 失擬 SS | B24: =B22-B23 | C24: '=B22-B23 | D24: 即 殘差SS − 純誤差SS：各濃度平均離「直線」多遠
A25: df_純誤差 | B25: =COUNT(B2:B16)-5 | C25: '=COUNT(B2:B16)-5 | D25: N − 濃度數 = 15−5
A26: df_失擬 | B26: =5-2 | C26: '=5-2 | D26: 濃度數 − 直線參數數(斜率+截距)
A27: F | B27: =(B24/B26)/(B23/B25) | C27: '=(B24/B26)/(B23/B25)
A28: p 值（失擬檢定） | B28: =_xlfn.F.DIST.RT(B27,B26,B25) | C28: '=F.DIST.RT(B27,B26,B25) | D28: p 大才好：不顯著代表看不出直線不夠用（不等於「證明」是直線）
A30: 這組資料高濃度時散布明顯較大（詳見 Ch04 的加權迴歸範例）；本檢定看的是「彎不彎」，不是變異是否均齊。

Sheet 對照R答案
A1: 項目 | B1: Excel 算出來 | C1: R 的答案 | D1: 一致？ | E1: 來源儲存格
A2: 雙因子：SS_total | B2: ='雙因子ANOVA'!B26 | C2: 2585.925 | D2: =IF(ABS(B2-C2)<=1.2929625,"✓","✗") | E2: '雙因子ANOVA'!B26
A3: 雙因子：SS_A（溫度） | B3: ='雙因子ANOVA'!B28 | C3: 1883.25 | D3: =IF(ABS(B3-C3)<=0.941625,"✓","✗") | E3: '雙因子ANOVA'!B28
A4: 雙因子：SS_B（時間） | B4: ='雙因子ANOVA'!B29 | C4: 441.045 | D4: =IF(ABS(B4-C4)<=0.2205225,"✓","✗") | E4: '雙因子ANOVA'!B29
A5: 雙因子：SS_AB（交互作用） | B5: ='雙因子ANOVA'!B30 | C5: 250.80333 | D5: =IF(ABS(B5-C5)<=0.12540166665,"✓","✗") | E5: '雙因子ANOVA'!B30
A6: 雙因子：F_A | B6: ='雙因子ANOVA'!B40 | C6: 1043.673 | D6: =IF(ABS(B6-C6)<=0.521836515,"✓","✗") | E6: '雙因子ANOVA'!B40
A7: 雙因子：F_AB | B7: ='雙因子ANOVA'!B42 | C7: 138.992 | D7: =IF(ABS(B7-C7)<=0.06949599755,"✓","✗") | E7: '雙因子ANOVA'!B42
A8: 雙因子：p_AB | B8: ='雙因子ANOVA'!B45 | C8: 5.0216142e-09 | D8: =IF(ABS(B8-C8)<=1e-12,"✓","✗") | E8: '雙因子ANOVA'!B45
A9: 精密度：s_r | B9: ='ISO5725精密度分解'!B19 | C9: 0.093202289 | D9: =IF(ABS(B9-C9)<=4.660114448e-05,"✓","✗") | E9: 'ISO5725精密度分解'!B19
A10: 精密度：s_between | B10: ='ISO5725精密度分解'!B20 | C10: 0.091536271 | D10: =IF(ABS(B10-C10)<=4.5768135444999996e-05,"✓","✗") | E10: 'ISO5725精密度分解'!B20
A11: 精密度：s_I | B11: ='ISO5725精密度分解'!B21 | C11: 0.1306352 | D11: =IF(ABS(B11-C11)<=6.531760015000001e-05,"✓","✗") | E11: 'ISO5725精密度分解'!B21
A12: 精密度：全部丟進STDEV.S | B12: ='ISO5725精密度分解'!B22 | C12: 0.12597052 | D12: =IF(ABS(B12-C12)<=6.298525905e-05,"✓","✗") | E12: 'ISO5725精密度分解'!B22
A13: 精密度：正確的當天平均不確定度 | B13: ='ISO5725精密度分解'!B24 | C13: 0.10618119 | D13: =IF(ABS(B13-C13)<=5.309059345e-05,"✓","✗") | E13: 'ISO5725精密度分解'!B24
A14: 失擬：殘差SS | B14: ='失擬檢定'!B22 | C14: 229158.75 | D14: =IF(ABS(B14-C14)<=0.5,"✓","✗") | E14: '失擬檢定'!B22
A15: 失擬：純誤差SS | B15: ='失擬檢定'!B23 | C15: 228110.67 | D15: =IF(ABS(B15-C15)<=0.5,"✓","✗") | E15: '失擬檢定'!B23
A16: 失擬：失擬SS | B16: ='失擬檢定'!B24 | C16: 1048.0817 | D16: =IF(ABS(B16-C16)<=0.2,"✓","✗") | E16: '失擬檢定'!B24
A17: 失擬：F | B17: ='失擬檢定'!B27 | C17: 0.015315398 | D17: =IF(ABS(B17-C17)<=7.657699030000001e-06,"✓","✗") | E17: '失擬檢定'!B27
A18: 失擬：p | B18: ='失擬檢定'!B28 | C18: 0.99723948 | D18: =IF(ABS(B18-C18)<=0.00049861974235,"✓","✗") | E18: '失擬檢定'!B28
A20: 如果你改了黃色儲存格的數據，這裡當然會變成 ✗——那是因為 R 的答案是用原始教材數據算的。
